<?xml version="1.0" encoding="utf-8"?><testsuites><testsuite errors="0" failures="6" hostname="x202e" name="pytest" skipped="0" tests="12" time="0.437" timestamp="2019-09-06T17:16:57.238515"><testcase classname="test_submit.TestChalange2" file="test_submit.py" line="6" name="test_instance_class" time="0.006"></testcase><testcase classname="test_submit.TestChalange2" file="test_submit.py" line="10" name="test_protected_attribute_manager" time="0.002"></testcase><testcase classname="test_submit.TestChalange2" file="test_submit.py" line="15" name="test_protected_attribute" time="0.002"></testcase><testcase classname="test_submit.TestChalange2" file="test_submit.py" line="20" name="test_total_hours_seller" time="0.002"></testcase><testcase classname="test_submit.TestChalange2" file="test_submit.py" line="24" name="test_total_hours_manager" time="0.002"></testcase><testcase classname="test_submit.TestChalange2" file="test_submit.py" line="28" name="test_get_department_seller" time="0.002"><failure message="AttributeError: &apos;Seller&apos; object has no attribute &apos;get_departament&apos;">E   AttributeError: &apos;Seller&apos; object has no attribute &apos;get_departament&apos;</failure></testcase><testcase classname="test_submit.TestChalange2" file="test_submit.py" line="32" name="test_get_department_manager" time="0.003"><failure message="AttributeError: &apos;Manager&apos; object has no attribute &apos;get_departament&apos;">E   AttributeError: &apos;Manager&apos; object has no attribute &apos;get_departament&apos;</failure></testcase><testcase classname="test_submit.TestChalange2" file="test_submit.py" line="36" name="test_sales_seller" time="0.007"><failure message="TypeError: &apos;int&apos; object is not callable">E   TypeError: &apos;int&apos; object is not callable</failure></testcase><testcase classname="test_submit.TestChalange2" file="test_submit.py" line="42" name="test_protected_attribute_sales" time="0.004"><failure message="Failed: DID NOT RAISE &lt;class &apos;AttributeError&apos;&gt;">E   Failed: DID NOT RAISE &lt;class &apos;AttributeError&apos;&gt;</failure></testcase><testcase classname="test_submit.TestChalange2" file="test_submit.py" line="47" name="test_calc_bonus_seller" time="0.006"><failure message="TypeError: &apos;int&apos; object is not callable">E   TypeError: &apos;int&apos; object is not callable</failure></testcase><testcase classname="test_submit.TestChalange2" file="test_submit.py" line="53" name="test_calc_bonus_manger" time="0.005"><system-out>18.45
</system-out></testcase><testcase classname="test_submit.TestChalange2" file="test_submit.py" line="57" name="test_get_sales_manger" time="0.003"><failure message="TypeError: &apos;int&apos; object is not callable">E   TypeError: &apos;int&apos; object is not callable</failure></testcase></testsuite></testsuites>